Workbook

Sheet 논문 update_25.09.03
A1: 연번 | B1: 논문 | C1: 논문 구분 | D1: 발표지 | E1: 발표일자 | F1: 발표자 | H1: 총저자수 | I1: 역할 | J1: IF | K1: Top % | L1: File link
A2: =ROW()-1 -> 1 | B2: Experimental performance evaluation of isothermal dehumidification and indirect evaporative cooling-assisted dedicated outdoor air system | C2: Journal paper | D2: Energy Conversion and Management | E2: 2026.01.15 | F2: HJ Cho, SY Cheon, K Jang, B Kim, JW Jeong | G2: 348, 120715 | H2: 5 | I2: 공동저자 | J2: =IFERROR(VLOOKUP(TRIM(D2),'JCR update_25.09.03'!$A$2:$B$20,2,FALSE),"-") -> 10.9 | K2: =IFERROR(VLOOKUP(TRIM(D2),'JCR update_25.09.03'!$A:$H,6,FALSE),"-") -> 2.3391813
A3: =ROW()-1 -> 2 | B3: The Feasibility Study on the Hollow Fiber Membrane Dehumidification System Coupling with Conventional Air Conditioning System | C3: Conference paper | D3: REHVA HVAC World Congress | E3: 2025 | F3: K Tsuji, G Yoon, HJ Cho, SY Cheon, JW Jeong | G3: 792-800 | H3: 5 | I3: 공동저자 | J3: - | K3: -
A4: =ROW()-1 -> 3 | B4: System design and performance assessment of hollow fiber membrane-based humidifier for HVAC applications | C4: Journal paper | D4: Applied Thermal Engineering | E4: 2025.04.15 | F4: HJ Cho, SY Cheon, SH Park, JW Jeong | G4: 265, 125603 | H4: 4 | I4: 공동저자 | J4: =IFERROR(VLOOKUP(TRIM(D4),'JCR update_25.09.03'!$A$2:$B$20,2,FALSE),"-") -> 6.9 | K4: =IFERROR(VLOOKUP(TRIM(D4),'JCR update_25.09.03'!$A:$H,6,FALSE),"-") -> 4.9450549 | L4: https://www.dropbox.com/scl/fi/9ubb46x48dkjaoopdfvw7/ATE_265_2025_125603.pdf?rlkey=f89a7xv9ybn0z5ffw6rio6pjj&dl=0
A5: =ROW()-1 -> 4 | B5: Energy saving of vacuum-based membrane dehumidification with indirect evaporative cooling in a low sensible-heat-ratio building | C5: Journal paper | D5: Journal of Building Engineering | E5: 2024.11.01 | F5: SH Park, SY Cheon, HJ Cho, JW Jeong | G5: 96, 110490 | H5: 4 | I5: 공동저자 | J5: =IFERROR(VLOOKUP(TRIM(D5),'JCR update_25.09.03'!$A$2:$B$20,2,FALSE),"-") -> 7.4 | K5: =IFERROR(VLOOKUP(TRIM(D5),'JCR update_25.09.03'!$A:$H,6,FALSE),"-") -> 5.4644809 | L5: https://www.dropbox.com/scl/fi/8r84rg185gdbk86ddxmqf/JOBE_96_2024_110490.pdf?rlkey=222qvl37t33z0xawcy3rgko9e&dl=0
A6: =ROW()-1 -> 5 | B6: Applicability of a dedicated outdoor air system assisted by isothermal dehumidification and evaporative cooling | C6: Journal paper | D6: Journal of Building Engineering | E6: 2024.04.01 | F6: SY Cheon, HJ Cho, JW Jeong | G6: 82, 108169 | H6: 3 | I6: 제1저자 | J6: =IFERROR(VLOOKUP(TRIM(D6),'JCR update_25.09.03'!$A$2:$B$20,2,FALSE),"-") -> 7.4 | K6: =IFERROR(VLOOKUP(TRIM(D6),'JCR update_25.09.03'!$A:$H,6,FALSE),"-") -> 5.4644809 | L6: https://www.dropbox.com/scl/fi/a9vkefnsnivy0vc5wzhrg/JOBE_82_2024_108169.pdf?rlkey=9alui6f89p23jz71cf2kyycwt&dl=0
A7: =ROW()-1 -> 6 | B7: Experimental analysis of vacuum membrane dehumidifier: Hollow fiber module designs and dehumidification performance | C7: Journal paper | D7: Applied Thermal Engineering | E7: 2024.01.10 | F7: HJ Cho, SY Cheon, JW Jeong, G Yoon | G7: 236, 121848 | H7: 4 | I7: 공동저자 | J7: =IFERROR(VLOOKUP(TRIM(D7),'JCR update_25.09.03'!$A$2:$B$20,2,FALSE),"-") -> 6.9 | K7: =IFERROR(VLOOKUP(TRIM(D7),'JCR update_25.09.03'!$A:$H,6,FALSE),"-") -> 4.9450549 | L7: https://www.dropbox.com/scl/fi/qu5jjqnew2yp882jz54or/ATE_236_2024_121848.pdf?rlkey=jzjdopdzhh0q2kos4j8z8bjkg&dl=0
A8: =ROW()-1 -> 7 | B8: Preliminary Test on Moisture Transfer of Flat Sheet Membrane-based Dehumidification System | C8: Conference paper | D8: Purdue conference | E8: 2024 | F8: HJ Cho, SY Cheon, SJ Lee, JW Jeong | H8: - | I8: - | J8: =IFERROR(VLOOKUP(TRIM(D8),'JCR update_25.09.03'!$A$2:$B$20,2,FALSE),"-") -> - | K8: =IFERROR(VLOOKUP(TRIM(D8),'JCR update_25.09.03'!$A:$H,6,FALSE),"-") -> -
A9: =ROW()-1 -> 8 | B9: Thermodynamic Analysis of Cascade Vacuum Pump Based Membrane Dehumidifier in Air Conditioning System | C9: Conference paper | D9: Purdue conference | E9: 2024 | F9: SY Cheon, HJ Cho, JH Lee, SH Park, JW Jeong | H9: - | I9: - | J9: =IFERROR(VLOOKUP(TRIM(D9),'JCR update_25.09.03'!$A$2:$B$20,2,FALSE),"-") -> - | K9: =IFERROR(VLOOKUP(TRIM(D9),'JCR update_25.09.03'!$A:$H,6,FALSE),"-") -> -
A10: =ROW()-1 -> 9 | B10: Exergy analysis on the low flow rate of solution in the atomization-based liquid desiccant system | C10: Conference paper | D10: Journal of Physics: Conference | E10: 2023 | F10: SJ Lee, SY Cheon, S Kim, TD Kwon, JW Jeong | G10: 2600 (6), 062007 | H10: - | I10: - | J10: =IFERROR(VLOOKUP(TRIM(D10),'JCR update_25.09.03'!$A$2:$B$20,2,FALSE),"-") -> - | K10: =IFERROR(VLOOKUP(TRIM(D10),'JCR update_25.09.03'!$A:$H,6,FALSE),"-") -> -
A11: =ROW()-1 -> 10 | B11: Applicability of a liquid-desiccant air-conditioning system in energy-efficient buildings with high latent load | C11: Journal paper | D11: Journal of Building Engineering | E11: 2023.11.01 | F11: JH Lee, SY Cheon, SJ Lee, HJ Cho, JW Jeong | G11: 78, 107608 | H11: 5 | I11: 공동저자 | J11: =IFERROR(VLOOKUP(TRIM(D11),'JCR update_25.09.03'!$A$2:$B$20,2,FALSE),"-") -> 7.4 | K11: =IFERROR(VLOOKUP(TRIM(D11),'JCR update_25.09.03'!$A:$H,6,FALSE),"-") -> 5.4644809 | L11: https://www.dropbox.com/scl/fi/9pqbk4dvabmap8l7p17wr/JOBE_78_2023_107608.pdf?rlkey=8x4dta3nzvkp0jeqishad92bc&dl=0
A12: =ROW()-1 -> 11 | B12: Energy saving potential of latent heat exchanger-integrated dual core energy recovery ventilator | C12: Journal paper | D12: Applied Thermal Engineering | E12: 2023.08.01 | F12: HJ Cho, SY Cheon, JW Jeong | G12: 231, 120989 | H12: 3 | I12: 공동저자 | J12: =IFERROR(VLOOKUP(TRIM(D12),'JCR update_25.09.03'!$A$2:$B$20,2,FALSE),"-") -> 6.9 | K12: =IFERROR(VLOOKUP(TRIM(D12),'JCR update_25.09.03'!$A:$H,6,FALSE),"-") -> 4.9450549 | L12: https://www.dropbox.com/scl/fi/folykm8yzjyj7ahtahk4a/ATE_231_2023_120989.pdf?rlkey=z79bhqj6c75stbhmdnrvzidj8&dl=0
A13: =ROW()-1 -> 12 | B13: Impact of external electric resistance on the power generation in the thermoelectric energy harvesting blocks | C13: Journal paper | D13: Renewable Energy | E13: 2023.08.01 | F13: J Joung, SY Cheon, YK Kang, M Kim, J Park, JW Jeong | G13: 212, 779-791 | H13: 6 | I13: 공동저자 | J13: =IFERROR(VLOOKUP(TRIM(D13),'JCR update_25.09.03'!$A$2:$B$20,2,FALSE),"-") -> 9.1 | K13: =IFERROR(VLOOKUP(TRIM(D13),'JCR update_25.09.03'!$A:$H,6,FALSE),"-") -> 17.647059 | L13: https://www.dropbox.com/scl/fi/ysabwm6g2dpdmyuwd91ir/ER_212_2023_779_791.pdf?rlkey=5hp62p5q1atqjr1li427ka1x0&dl=0
A14: =ROW()-1 -> 13 | B14: Energy retrofit of public office building through liquid desiccant assisted dedicated outdoor air system with fuel cell in Korea | C14: Journal paper | D14: Applied Thermal Engineering | E14: 2023.07.25 | F14: H Lim, SY Cheon, HJ Cho, JW Jeong, Y Su | G14: 230, 120870 | H14: 5 | I14: 공동저자 | J14: =IFERROR(VLOOKUP(TRIM(D14),'JCR update_25.09.03'!$A$2:$B$20,2,FALSE),"-") -> 6.9 | K14: =IFERROR(VLOOKUP(TRIM(D14),'JCR update_25.09.03'!$A:$H,6,FALSE),"-") -> 4.9450549 | L14: https://www.dropbox.com/scl/fi/i62yc6j3j3g1gqn64nnf8/ATE_230_2023_120870.pdf?rlkey=hp9vook17dsfgul97tnuvbokd&dl=0
A15: =ROW()-1 -> 14 | B15: Multi-objective optimization for capacity matching and energy performance of heat-pump-driven liquid-desiccant air-conditioning system | C15: Journal paper | D15: Applied Thermal Engineering | E15: 2023.07.05 | F15: JH Lee, SY Cheon, JW Jeong | G15: 229, 120615 | H15: 3 | I15: 공동저자 | J15: =IFERROR(VLOOKUP(TRIM(D15),'JCR update_25.09.03'!$A$2:$B$20,2,FALSE),"-") -> 6.9 | K15: =IFERROR(VLOOKUP(TRIM(D15),'JCR update_25.09.03'!$A:$H,6,FALSE),"-") -> 4.9450549 | L15: https://www.dropbox.com/scl/fi/0lxhtwebs5ujjz4o9a98a/ATE_229_2023_120615.pdf?rlkey=vm0ak60aomtad4d73lmzx850a&dl=0
A16: =ROW()-1 -> 15 | B16: Design and energy performance of the heat pump-driven liquid desiccant system with an ultrasonic atomization | C16: Conference paper | D16: IEA | E16: 2023 | F16: SJ Lee, SY Cheon, SY Jo, JW Joung, JW Jeong | H16: - | I16: - | J16: =IFERROR(VLOOKUP(TRIM(D16),'JCR update_25.09.03'!$A$2:$B$20,2,FALSE),"-") -> - | K16: =IFERROR(VLOOKUP(TRIM(D16),'JCR update_25.09.03'!$A:$H,6,FALSE),"-") -> -
A17: =ROW()-1 -> 16 | B17: Theoretical analysis of membrane based liquid desiccant air conditioning system | C17: Conference paper | D17: IEA | E17: 2023 | F17: SY Cheon, BJ Kim, JH Lee, M Kim, HL Park, JW Jeong | H17: - | I17: - | J17: =IFERROR(VLOOKUP(TRIM(D17),'JCR update_25.09.03'!$A$2:$B$20,2,FALSE),"-") -> - | K17: =IFERROR(VLOOKUP(TRIM(D17),'JCR update_25.09.03'!$A:$H,6,FALSE),"-") -> -
A18: =ROW()-1 -> 17 | B18: Experimental analysis on energy recovery ventilator with latent heat exchanger using hollow fiber membrane | C18: Journal paper | D18: Energy Conversion and Management | E18: 2023.02.15 | F18: HJ Cho, SY Cheon, JW Jeong | G18: 278, 116706 | H18: 3 | I18: 공동저자 | J18: =IFERROR(VLOOKUP(TRIM(D18),'JCR update_25.09.03'!$A$2:$B$20,2,FALSE),"-") -> 10.9 | K18: =IFERROR(VLOOKUP(TRIM(D18),'JCR update_25.09.03'!$A:$H,6,FALSE),"-") -> 2.3391813 | L18: https://www.dropbox.com/scl/fi/drnh5a2j5f7uvf025hjij/ECM_278_2023_116706.pdf?rlkey=1voeb7tupdbnqt0ktlys2locj&dl=0
A19: =ROW()-1 -> 18 | B19: Humidification Performance Evaluation of hollow-fiber membrane-based humidifier for air-conditioning | C19: Conference paper | D19: E3S Web of Conferences | E19: 2023 | F19: SY Jo, SY Cheon, BJ Kim, TD Kwon, JW Jeong | G19: 396, 01099 | H19: - | I19: - | J19: =IFERROR(VLOOKUP(TRIM(D19),'JCR update_25.09.03'!$A$2:$B$20,2,FALSE),"-") -> - | K19: =IFERROR(VLOOKUP(TRIM(D19),'JCR update_25.09.03'!$A:$H,6,FALSE),"-") -> -
A20: =ROW()-1 -> 19 | B20: Experimental study of vacuum-based membrane dehumidifier for HVAC system: Parametric analysis and dehumidification performance | C20: Journal paper | D20: Energy Conversion and Management | E20: 2022.10.15 | F20: SY Cheon, HJ Cho, JW Jeong | G20: 270, 116252 | H20: 3 | I20: 제1저자 | J20: =IFERROR(VLOOKUP(TRIM(D20),'JCR update_25.09.03'!$A$2:$B$20,2,FALSE),"-") -> 10.9 | K20: =IFERROR(VLOOKUP(TRIM(D20),'JCR update_25.09.03'!$A:$H,6,FALSE),"-") -> 2.3391813 | L20: https://www.dropbox.com/scl/fi/qhwz35oa7cfntnjauzz25/ECM_270_2022_116252.pdf?rlkey=wsugfym3lp2cgk7uam96e6gl6&dl=0
A21: =ROW()-1 -> 20 | B21: Development of empirical models to predict latent heat exchange performance for hollow fiber membrane-based ventilation system | C21: Journal paper | D21: Applied Thermal Engineering | E21: 2022.08.01 | F21: HJ Cho, SY Cheon, JW Jeong | G21: 213, 118686 | H21: 3 | I21: 공동저자 | J21: =IFERROR(VLOOKUP(TRIM(D21),'JCR update_25.09.03'!$A$2:$B$20,2,FALSE),"-") -> 6.9 | K21: =IFERROR(VLOOKUP(TRIM(D21),'JCR update_25.09.03'!$A:$H,6,FALSE),"-") -> 4.9450549 | L21: https://www.dropbox.com/scl/fi/eurjrmbhd6wfc760kr4r3/ATE_213_2022_118686.pdf?rlkey=rvawo37q9wc6j1d6ejjs9lnjx&dl=0
A22: =ROW()-1 -> 21 | B22: Simplified effectiveness and number of transfer unit model for a vacuum membrane dehumidifier applied to air conditioning | C22: Journal paper | D22: Applied Thermal Engineering | E22: 2022.06.25 | F22: SY Cheon, HJ Cho, JW Jeong | G22: 210, 118404 | H22: 3 | I22: 제1저자 | J22: =IFERROR(VLOOKUP(TRIM(D22),'JCR update_25.09.03'!$A$2:$B$20,2,FALSE),"-") -> 6.9 | K22: =IFERROR(VLOOKUP(TRIM(D22),'JCR update_25.09.03'!$A:$H,6,FALSE),"-") -> 4.9450549 | L22: https://www.dropbox.com/scl/fi/p0u1ef1wxlms0o7j5and4/ATE_210_2022_118404.pdf?rlkey=tafi2mwrnjd67b5mdk73cyw54&dl=0
A23: =ROW()-1 -> 22 | B23: Design of a thermoelectric generator-assisted energy harvesting block considering melting temperature of phase change materials | C23: Journal paper | D23: Renewable Energy | E23: 2022.06.01 | F23: J Ko, SY Cheon, YK Kang, JW Jeong | G23: 193, 89-112 | H23: 4 | I23: 공동저자 | J23: =IFERROR(VLOOKUP(TRIM(D23),'JCR update_25.09.03'!$A$2:$B$20,2,FALSE),"-") -> 9.1 | K23: =IFERROR(VLOOKUP(TRIM(D23),'JCR update_25.09.03'!$A:$H,6,FALSE),"-") -> 17.647059 | L23: https://www.dropbox.com/scl/fi/2tdxn3rzd6qrwzzdoku03/ER_193_2022_89_112.pdf?rlkey=qd78wwxmu3qepdpikpi975tkd&dl=0
A24: =ROW()-1 -> 23 | B24: Experimental investigation on a packaged unit of membrane dehumidification-based ventilation system | C24: Conference paper | D24: CLIMA | E24: 2022 | F24: HY Cho, SY Cheon, SY Jo, SJ Lee, GB Lee , JW Jeong | H24: - | I24: - | J24: =IFERROR(VLOOKUP(TRIM(D24),'JCR update_25.09.03'!$A$2:$B$20,2,FALSE),"-") -> - | K24: =IFERROR(VLOOKUP(TRIM(D24),'JCR update_25.09.03'!$A:$H,6,FALSE),"-") -> -
A25: =ROW()-1 -> 24 | B25: Preliminary study on air-to-air latent heat exchanger fabricated using hollow fiber composite membrane for air-conditioning applications | C25: Journal paper | D25: Energy conversion and management | E25: 2022.01.01 | F25: HJ Cho, SY Cheon, JW Jeong | G25: 251, 115000 | H25: 3 | I25: 공동저자 | J25: =IFERROR(VLOOKUP(TRIM(D25),'JCR update_25.09.03'!$A$2:$B$20,2,FALSE),"-") -> 10.9 | K25: =IFERROR(VLOOKUP(TRIM(D25),'JCR update_25.09.03'!$A:$H,6,FALSE),"-") -> 2.3391813 | L25: https://www.dropbox.com/scl/fi/fhdoyu4pd7xubyc13uvn6/ECM_251_2022_115000.pdf?rlkey=430pgai8tt5waerosb1gfixyy&dl=0
A26: =ROW()-1 -> 25 | B26: Performance Analysis of a Passive Mixing Strategy assisted Heat-Pump-driven Liquid-Desiccant Air-Conditioning System | C26: Conference paper | D26: E3S Web of Conferences | E26: 2022 | F26: JH Lee, SY Cheon, M Kim, HL Park, JW Jeong | G26: 356, 1-4 | H26: - | I26: - | J26: =IFERROR(VLOOKUP(TRIM(D26),'JCR update_25.09.03'!$A$2:$B$20,2,FALSE),"-") -> - | K26: =IFERROR(VLOOKUP(TRIM(D26),'JCR update_25.09.03'!$A:$H,6,FALSE),"-") -> -
A27: =ROW()-1 -> 26 | B27: Phase-change material-integrated thermoelectric radiant panel: Experimental performance analysis and system design | C27: Journal paper | D27: Applied Thermal Engineering | E27: 2021.07.25 | F27: YK Kang, H Lim, SY Cheon, JW Jeong | G27: 194, 117082 | H27: 4 | I27: 공동저자 | J27: =IFERROR(VLOOKUP(TRIM(D27),'JCR update_25.09.03'!$A$2:$B$20,2,FALSE),"-") -> 6.9 | K27: =IFERROR(VLOOKUP(TRIM(D27),'JCR update_25.09.03'!$A:$H,6,FALSE),"-") -> 4.9450549 | L27: https://www.dropbox.com/scl/fi/unvnitg0skd2epjoalwm9/ATE_194_2021_117082.pdf?rlkey=raxctc5uskgcmg5qe2erfqa2q&dl=0
A28: =ROW()-1 -> 27 | B28: Energy impact of vacuum-based membrane dehumidification in building air-conditioning applications | C28: Journal paper | D28: Applied Thermal Engineering | E28: 2021.01.05 | F28: HJ Cho, SY Cheon, JW Jeong | G28: 182, 116094 | H28: 3 | I28: 공동저자 | J28: =IFERROR(VLOOKUP(TRIM(D28),'JCR update_25.09.03'!$A$2:$B$20,2,FALSE),"-") -> 6.9 | K28: =IFERROR(VLOOKUP(TRIM(D28),'JCR update_25.09.03'!$A:$H,6,FALSE),"-") -> 4.9450549 | L28: https://www.dropbox.com/scl/fi/ccui3ey4v9dz32glo3gie/ATE_182_2021_116094.pdf?rlkey=087cmdwae8wkud8hz5elqoerq&dl=0
A29: =ROW()-1 -> 28 | B29: Energy saving potential of a vacuum-based membrane dehumidifier in a dedicated outdoor air system | C29: Journal paper | D29: Energy Conversion and Management | E29: 2021.01.01 | F29: SY Cheon, HJ Cho, JW Jeong | G29: 227, 113618 | H29: 3 | I29: 제1저자 | J29: =IFERROR(VLOOKUP(TRIM(D29),'JCR update_25.09.03'!$A$2:$B$20,2,FALSE),"-") -> 10.9 | K29: =IFERROR(VLOOKUP(TRIM(D29),'JCR update_25.09.03'!$A:$H,6,FALSE),"-") -> 2.3391813 | L29: https://www.dropbox.com/scl/fi/8jni15dhs1dk502kcmip0/ECM_227_2021_113618.pdf?rlkey=8e149h0wxr1ulju883jpzhuj1&dl=0
A30: =ROW()-1 -> 29 | B30: Phase-Change Material Design for Thermoelectric Generator-Assisted Building Integrated Photovoltaic | C30: Conference paper | D30: ASHRAE | E30: 2021 | F30: J Ko, SY Cheon | G30: 127, 100-107 | H30: - | I30: - | J30: =IFERROR(VLOOKUP(TRIM(D30),'JCR update_25.09.03'!$A$2:$B$20,2,FALSE),"-") -> - | K30: =IFERROR(VLOOKUP(TRIM(D30),'JCR update_25.09.03'!$A:$H,6,FALSE),"-") -> -
A31: =ROW()-1 -> 30 | B31: Experimental Study on Dehumidification Performance of a Vacuum-Based Membrane Dehumidifier | C31: Conference paper | D31: ASHRAE | E31: 2021 | F31: SY Cheon, SJ Lee, LH Lin | G31: 127, 457-465 | H31: - | I31: - | J31: =IFERROR(VLOOKUP(TRIM(D31),'JCR update_25.09.03'!$A$2:$B$20,2,FALSE),"-") -> - | K31: =IFERROR(VLOOKUP(TRIM(D31),'JCR update_25.09.03'!$A:$H,6,FALSE),"-") -> -
A32: =ROW()-1 -> 31 | B32: Energy Performance of Desiccant and Evaporative Cooling-assisted 100% Outdoor Air System Combined with a Thermoelectric Module and Organic Rankine Cycle | C32: Conference paper | D32: Building Simulation | E32: 2019 | F32: SY Yoon, JY Park, SY Cheon, S Liu, JW Jeong | G32: 16, 3963-3967 | H32: - | I32: - | J32: =IFERROR(VLOOKUP(TRIM(D32),'JCR update_25.09.03'!$A$2:$B$20,2,FALSE),"-") -> - | K32: =IFERROR(VLOOKUP(TRIM(D32),'JCR update_25.09.03'!$A:$H,6,FALSE),"-") -> -
A33: =ROW()-1 -> 32 | B33: Applicability of thermoelectric heat pump in a dedicated outdoor air system | C33: Journal paper | D33: Energy | E33: 2019.04.15 | F33: SY Cheon, H Lim, JW Jeong | G33: 173, 244-262 | H33: 3 | I33: 제1저자 | J33: =IFERROR(VLOOKUP(TRIM(D33),'JCR update_25.09.03'!$A$2:$B$20,2,FALSE),"-") -> 9.4 | K33: =IFERROR(VLOOKUP(TRIM(D33),'JCR update_25.09.03'!$A:$H,6,FALSE),"-") -> 3.7974684 | L33: https://www.dropbox.com/scl/fi/cesfxohgth8kon1g0l75y/EGY_173_2019_244_262.pdf?rlkey=y698c1va9i9hkeptx4f2ebvjf&dl=0
A34: =ROW()-1 -> 33 | B34: Experimental analysis of dehumidification performance of counter and cross-flow liquid desiccant dehumidifiers | C34: Journal paper | D34: Applied Thermal Engineering | E34: 2019.03.05 | F34: HJ Cho, SY Cheon, JW Jeong | G34: 150, 210-223 | H34: 3 | I34: 공동저자 | J34: =IFERROR(VLOOKUP(TRIM(D34),'JCR update_25.09.03'!$A$2:$B$20,2,FALSE),"-") -> 6.9 | K34: =IFERROR(VLOOKUP(TRIM(D34),'JCR update_25.09.03'!$A:$H,6,FALSE),"-") -> 4.9450549 | L34: https://www.dropbox.com/scl/fi/zg3fswjb4vg2nyx5ka8pj/ATE_150_2019_210_223.pdf?rlkey=03zq1uruc4uilqep7t1sjo0qg&dl=0
A35: =ROW()-1 -> 34 | B35: Numerical Study of Heat Transfer in an Air-to-Air Heat Exchanger Integrated with a Thermoelectric Heat Pump | C35: Conference paper | D35: IBPSA | E35: 2019 | F35: SY Cheon, HW Dong, YK Kang, SJ Lee, JW Jeong | H35: - | I35: - | J35: =IFERROR(VLOOKUP(TRIM(D35),'JCR update_25.09.03'!$A$2:$B$20,2,FALSE),"-") -> - | K35: =IFERROR(VLOOKUP(TRIM(D35),'JCR update_25.09.03'!$A:$H,6,FALSE),"-") -> -
A36: =ROW()-1 -> 35 | B36: Energy-saving potential of dedicated outdoor-air system assisted by vacuum-based membrane dehumidifier | C36: Conference paper | D36: E3S Web of Conferences | E36: 2019 | F36: SY Cheon, SY Yoon, S Liu, JW Jeong | G36: 111, 01087 | H36: - | I36: - | J36: =IFERROR(VLOOKUP(TRIM(D36),'JCR update_25.09.03'!$A$2:$B$20,2,FALSE),"-") -> - | K36: =IFERROR(VLOOKUP(TRIM(D36),'JCR update_25.09.03'!$A:$H,6,FALSE),"-") -> -
A37: =ROW()-1 -> 36 | B37: A numerical model and validation of phase change material integrated thermoelectric radiant cooling panel | C37: Conference paper | D37: EDP Sciences | E37: 2019 | F37: H Lim, HJ Cho, SY Cheon, SJ Lee, JW Jeong | H37: - | I37: - | J37: =IFERROR(VLOOKUP(TRIM(D37),'JCR update_25.09.03'!$A$2:$B$20,2,FALSE),"-") -> - | K37: =IFERROR(VLOOKUP(TRIM(D37),'JCR update_25.09.03'!$A:$H,6,FALSE),"-") -> -
A38: =ROW()-1 -> 37 | B38: Energy-Harvesting Benefit of a Thermoelectric Generator for a Liquid Desiccant System in an Organic Rankine Cycle | C38: Conference paper | D38: Building Simulation | E38: 2019 | F38: SY Yoon, JY Park, SY Cheon, S Liu, JW Jeong | H38: - | I38: - | J38: =IFERROR(VLOOKUP(TRIM(D38),'JCR update_25.09.03'!$A$2:$B$20,2,FALSE),"-") -> - | K38: =IFERROR(VLOOKUP(TRIM(D38),'JCR update_25.09.03'!$A:$H,6,FALSE),"-") -> -
A39: =ROW()-1 -> 38 | B39: Empirical analysis for the heat exchange effectiveness of a thermoelectric liquid cooling and heating unit | C39: Journal paper | D39: Energies | E39: 2018.03.07 | F39: H Lim, SY Cheon, JW Jeong | G39: 11 (3), 580 | H39: 3 | I39: 공동저자 | J39: =IFERROR(VLOOKUP(TRIM(D39),'JCR update_25.09.03'!$A$2:$B$20,2,FALSE),"-") -> 3.2 | K39: =IFERROR(VLOOKUP(TRIM(D39),'JCR update_25.09.03'!$A:$H,6,FALSE),"-") -> 61.538462 | L39: https://www.dropbox.com/scl/fi/pho0s91qo0n50588yvl10/energies-11-00580.pdf?rlkey=yupqqxywcf3514a6v32yamq52&dl=0
A40: =ROW()-1 -> 39 | B40: Empirical Study on The Heat Exchange Effectiveness of A Cross-flow Thermoelectric Air To Air Heat Pump Unit | C40: Conference paper | D40: Purdue | E40: 2018 | F40: SY Cheon, JW Jeong | H40: - | I40: - | J40: =IFERROR(VLOOKUP(TRIM(D40),'JCR update_25.09.03'!$A$2:$B$20,2,FALSE),"-") -> - | K40: =IFERROR(VLOOKUP(TRIM(D40),'JCR update_25.09.03'!$A:$H,6,FALSE),"-") -> -
...

Sheet JCR update_25.09.03
A1: JCR (25.09.03)
A2: Journal | B2: IF | C2: Selectied CATEGORY | D2: Rank | E2: Number | F2: Top % | G2: JIF Quartile | H2: ISSN / EISSN | K2: Journal | L2: CATEGORY | M2: Top %
A3: Applied Thermal Engineering | B3: 6.9 | C3: ENGINEERING, MECHANICAL | D3: 9 | E3: 182 | F3: 4.9450549 | G3: Q1 | H3: 1359-4311 | K3: Energies | L3: ENERGY & FUELS | M3: ENERGY & FUELS
A4: Journal of Building Engineering | B4: 7.4 | C4: ENGINEERING, CIVIL | D4: 10 | E4: 183 | F4: 5.4644809 | G4: Q1 | H4: 2352-7102 | L4: 112/182 | M4: =112*100/182 -> 61.538462
A5: Renewable Energy | B5: 9.1 | C5: GREEN & SUSTAINABLE SCIENCE & TECHNOLOGY | D5: 18 | E5: 102 | F5: 17.647059 | G5: Q1 | H5: 0960-1481 | K5: Energy | L5: ENERGY & FUELS | M5: ENERGY & FUELS
A6: Energy Conversion and Management | B6: 10.9 | C6: MECHANICS | D6: 4 | E6: 171 | F6: 2.3391813 | G6: Q1 | H6: 0196-8904 | L6: 31/182 | M6: =100*31/182 -> 17.032967
A7: Energy | B7: 9.4 | C7: THERMODYNAMICS | D7: 3 | E7: 79 | F7: 3.7974684 | G7: Q1 | H7: 0360-5442 | K7: Energy | L7: THERMODYNAMICS | M7: THERMODYNAMICS
A8: Energies | B8: 3.2 | C8: ENERGY & FUELS | D8: 112 | E8: 182 | F8: 61.538462 | G8: Q3 | H8: 1996-1073 | L8: 3/79 | M8: =100*3/79 -> 3.7974684
K9: Energy Conversion and Management | L9: MECHANICS | M9: MECHANICS
L10: 4/171 | M10: =100*4/171 -> 2.3391813
K11: Energy Conversion and Management | L11: ENERGY & FUELS | M11: ENERGY & FUELS
L12: 21/182 | M12: =100*21/182 -> 11.538462
K13: Energy Conversion and Management | L13: THERMODYNAMICS | M13: THERMODYNAMICS
L14: 2/79 | M14: =100*2/79 -> 2.5316456
K15: Renewable Energy | L15: ENERGY & FUELS | M15: ENERGY & FUELS
L16: 34/182 | M16: =100*34/182 -> 18.681319
K17: Renewable Energy | L17: GREEN & SUSTAINABLE SCIENCE & TECHNOLOGY | M17: GREEN & SUSTAINABLE SCIENCE & TECHNOLOGY
L18: 18/102 | M18: =100*18/102 -> 17.647059
K19: Journal of Building Engineering | L19: CONSTRUCTION & BUILDING TECHNOLOGY | M19: CONSTRUCTION & BUILDING TECHNOLOGY
L20: 10/95 | M20: =100*10/95 -> 10.526316
K21: Journal of Building Engineering | L21: ENGINEERING, CIVIL | M21: ENGINEERING, CIVIL
L22: 10/183 | M22: =100*10/183 -> 5.4644809
K23: Applied Thermal Engineering | L23: ENERGY & FUELS | M23: ENERGY & FUELS
L24: 50/182 | M24: =100*50/182 -> 27.472527
K25: Applied Thermal Engineering | L25: ENGINEERING, MECHANICAL | M25: ENGINEERING, MECHANICAL
L26: 9/182 | M26: =100*9/182 -> 4.9450549
K27: Applied Thermal Engineering | L27: MECHANICS | M27: MECHANICS
L28: 9/171 | M28: =100*9/171 -> 5.2631579
K29: Applied Thermal Engineering | L29: THERMODYNAMICS | M29: THERMODYNAMICS
L30: 5/79 | M30: =100*5/79 -> 6.3291139
